Workbook

Sheet 총괄
B2: ■ 차단기 트립 관리 총괄 | H2: 26/02/03 ACTA기준 | M2: ■ KEY MISSON 대상(101국소외)
B3: 구분 | C3: 춘천 | D3: 양구 | E3: 홍천 | F3: 인제 | G3: 철원 | H3: 화천 | I3: 총대상 | M3: 구분 | N3: 춘천 | O3: 양구 | P3: 홍천 | Q3: 인제 | R3: 철원 | S3: 화천 | T3: 총대상 | V3: 중복출동건수 | X3: 1회 | Y3: 2회 | Z3: 3회 | AA3: 4회 | AB3: 5회
B4: 차단기 트립 | C4: =COUNTIFS('차단기 트립 진행 내역'!$B$4:$B$1048576,C3) -> 78 | D4: =COUNTIFS('차단기 트립 진행 내역'!$B$4:$B$1048576,D3) -> 24 | E4: =COUNTIFS('차단기 트립 진행 내역'!$B$4:$B$1048576,E3) -> 31 | F4: =COUNTIFS('차단기 트립 진행 내역'!$B$4:$B$1048576,F3) -> 14 | G4: =COUNTIFS('차단기 트립 진행 내역'!$B$4:$B$1048576,G3) -> 29 | H4: =COUNTIFS('차단기 트립 진행 내역'!$B$4:$B$1048576,H3) -> 19 | I4: =SUM(C4:H4) -> 195 | M4: 대상 | N4: =COUNTIFS('차단기 트립 진행 내역'!$B$4:$B$1048576,"춘천",'차단기 트립 진행 내역'!$P$4:$P$1048576,"대상") -> 46 | O4: =COUNTIFS('차단기 트립 진행 내역'!$B$4:$B$1048576,"양구",'차단기 트립 진행 내역'!$P$4:$P$1048576,"대상") -> 12 | P4: =COUNTIFS('차단기 트립 진행 내역'!$B$4:$B$1048576,"홍천",'차단기 트립 진행 내역'!$P$4:$P$1048576,"대상") -> 20 | Q4: =COUNTIFS('차단기 트립 진행 내역'!$B$4:$B$1048576,"인제",'차단기 트립 진행 내역'!$P$4:$P$1048576,"대상") -> 8 | R4: =COUNTIFS('차단기 트립 진행 내역'!$B$4:$B$1048576,"철원",'차단기 트립 진행 내역'!$P$4:$P$1048576,"대상") -> 23 | S4: =COUNTIFS('차단기 트립 진행 내역'!$B$4:$B$1048576,"화천",'차단기 트립 진행 내역'!$P$4:$P$1048576,"대상") -> 9 | T4: =SUM(N4:S4) -> 118 | V4: =SUM(X4:AA4) -> 118 | X4: =COUNTIFS('차단기 트립 진행 내역'!$P$4:$P$1048576,"대상",'차단기 트립 진행 내역'!$J$4:$J$1048576,1) -> 91 | Y4: =COUNTIFS('차단기 트립 진행 내역'!$P$4:$P$1048576,"대상",'차단기 트립 진행 내역'!$J$4:$J$1048576,2) -> 23 | Z4: =COUNTIFS('차단기 트립 진행 내역'!$P$4:$P$1048576,"대상",'차단기 트립 진행 내역'!$J$4:$J$1048576,3) -> 2 | AA4: =COUNTIFS('차단기 트립 진행 내역'!$P$4:$P$1048576,"대상",'차단기 트립 진행 내역'!$J$4:$J$1048576,4) -> 2 | AB4: =COUNTIFS('차단기 트립 진행 내역'!$P$4:$P$1048576,"대상",'차단기 트립 진행 내역'!$J$4:$J$1048576,0) -> 0
B5: 점검 완료 | C5: =C4-C6 -> 78 | D5: =D4-D6 -> 24 | E5: =E4-E6 -> 31 | F5: =F4-F6 -> 14 | G5: =G4-G6 -> 29 | H5: =H4-H6 -> 19 | I5: =SUM(C5:H5) -> 195 | M5: 점검 완료 | N5: =N4-N6 -> 46 | O5: =O4-O6 -> 12 | P5: =P4-P6 -> 20 | Q5: =Q4-Q6 -> 8 | R5: =R4-R6 -> 23 | S5: =S4-S6 -> 9 | T5: =T4-T6 -> 118
B6: 미점검 | C6: =COUNTIFS('차단기 트립 진행 내역'!$B$4:$B$1048576,"춘천",'차단기 트립 진행 내역'!$M$4:$M$1048576,"미점검") -> 0 | D6: =COUNTIFS('차단기 트립 진행 내역'!$B$4:$B$1048576,"양구",'차단기 트립 진행 내역'!$M$4:$M$1048576,"미점검") -> 0 | E6: =COUNTIFS('차단기 트립 진행 내역'!$B$4:$B$1048576,"홍천",'차단기 트립 진행 내역'!$M$4:$M$1048576,"미점검") -> 0 | F6: =COUNTIFS('차단기 트립 진행 내역'!$B$4:$B$1048576,"인제",'차단기 트립 진행 내역'!$M$4:$M$1048576,"미점검") -> 0 | G6: =COUNTIFS('차단기 트립 진행 내역'!$B$4:$B$1048576,"철원",'차단기 트립 진행 내역'!$M$4:$M$1048576,"미점검") -> 0 | H6: =COUNTIFS('차단기 트립 진행 내역'!$B$4:$B$1048576,"화천",'차단기 트립 진행 내역'!$M$4:$M$1048576,"미점검") -> 0 | I6: =SUM(C6:H6) -> 0 | M6: 미점검 | N6: =COUNTIFS('차단기 트립 진행 내역'!$B$4:$B$1048576,"춘천",'차단기 트립 진행 내역'!$P$4:$P$1048576,"대상",'차단기 트립 진행 내역'!$M$4:$M$1048576,"미점검") -> 0 | O6: =COUNTIFS('차단기 트립 진행 내역'!$B$4:$B$1048576,"양구",'차단기 트립 진행 내역'!$P$4:$P$1048576,"대상",'차단기 트립 진행 내역'!$M$4:$M$1048576,"미점검") -> 0 | P6: =COUNTIFS('차단기 트립 진행 내역'!$B$4:$B$1048576,"홍천",'차단기 트립 진행 내역'!$P$4:$P$1048576,"대상",'차단기 트립 진행 내역'!$M$4:$M$1048576,"미점검") -> 0 | Q6: =COUNTIFS('차단기 트립 진행 내역'!$B$4:$B$1048576,"인제",'차단기 트립 진행 내역'!$P$4:$P$1048576,"대상",'차단기 트립 진행 내역'!$M$4:$M$1048576,"미점검") -> 0 | R6: =COUNTIFS('차단기 트립 진행 내역'!$B$4:$B$1048576,"철원",'차단기 트립 진행 내역'!$P$4:$P$1048576,"대상",'차단기 트립 진행 내역'!$M$4:$M$1048576,"미점검") -> 0 | S6: =COUNTIFS('차단기 트립 진행 내역'!$B$4:$B$1048576,"화천",'차단기 트립 진행 내역'!$P$4:$P$1048576,"대상",'차단기 트립 진행 내역'!$M$4:$M$1048576,"미점검") -> 0 | T6: =SUM(N6:S6) -> 0 | V6: 절연저항 결과 | X6: 불량 | Y6: =COUNTIFS('차단기 트립 진행 내역'!$P$4:$P$1048576,"대상",'차단기 트립 진행 내역'!$L$4:$L$1048576,"불량") -> 13 | Z6: 측정불가 | AA6: =COUNTIFS('차단기 트립 진행 내역'!$P$4:$P$1048576,"대상",'차단기 트립 진행 내역'!$L$4:$L$1048576,"측정불가") -> 2
B7: 점검율 | C7: =C5/C4 -> 1 | D7: =D5/D4 -> 1 | E7: =E5/E4 -> 1 | F7: =F5/F4 -> 1 | G7: =G5/G4 -> 1 | H7: =H5/H4 -> 1 | I7: =I5/I4 -> 1 | M7: 점검율 | N7: =N5/N4 -> 1 | O7: =O5/O4 -> 1 | P7: =P5/P4 -> 1 | Q7: =Q5/Q4 -> 1 | R7: =R5/R4 -> 1 | S7: =S5/S4 -> 1 | T7: =T5/T4 -> 1 | X7: 양호 | Y7: =COUNTIFS('차단기 트립 진행 내역'!$P$4:$P$1048576,"대상",'차단기 트립 진행 내역'!$L$4:$L$1048576,"양호") -> 103
B9: 조치 완료 | C9: =COUNTIFS('차단기 트립 진행 내역'!$B$4:$B$1048576,"춘천",'차단기 트립 진행 내역'!$O$4:$O$1048576,"완료") -> 75 | D9: =COUNTIFS('차단기 트립 진행 내역'!$B$4:$B$1048576,"양구",'차단기 트립 진행 내역'!$O$4:$O$1048576,"완료") -> 23 | E9: =COUNTIFS('차단기 트립 진행 내역'!$B$4:$B$1048576,"홍천",'차단기 트립 진행 내역'!$O$4:$O$1048576,"완료") -> 29 | F9: =COUNTIFS('차단기 트립 진행 내역'!$B$4:$B$1048576,"인제",'차단기 트립 진행 내역'!$O$4:$O$1048576,"완료") -> 14 | G9: =COUNTIFS('차단기 트립 진행 내역'!$B$4:$B$1048576,"철원",'차단기 트립 진행 내역'!$O$4:$O$1048576,"완료") -> 28 | H9: =COUNTIFS('차단기 트립 진행 내역'!$B$4:$B$1048576,"화천",'차단기 트립 진행 내역'!$O$4:$O$1048576,"완료") -> 18 | I9: =SUM(C9:H9) -> 187 | M9: 조치 완료 | N9: =COUNTIFS('차단기 트립 진행 내역'!$B$4:$B$1048576,"춘천",'차단기 트립 진행 내역'!$P$4:$P$1048576,"대상",'차단기 트립 진행 내역'!$M$4:$M$1048576,"조치완료") -> 44 | O9: =COUNTIFS('차단기 트립 진행 내역'!$B$4:$B$1048576,"양구",'차단기 트립 진행 내역'!$P$4:$P$1048576,"대상",'차단기 트립 진행 내역'!$M$4:$M$1048576,"조치완료") -> 11 | P9: =COUNTIFS('차단기 트립 진행 내역'!$B$4:$B$1048576,"홍천",'차단기 트립 진행 내역'!$P$4:$P$1048576,"대상",'차단기 트립 진행 내역'!$M$4:$M$1048576,"조치완료") -> 19 | Q9: =COUNTIFS('차단기 트립 진행 내역'!$B$4:$B$1048576,"인제",'차단기 트립 진행 내역'!$P$4:$P$1048576,"대상",'차단기 트립 진행 내역'!$M$4:$M$1048576,"조치완료") -> 8 | R9: =COUNTIFS('차단기 트립 진행 내역'!$B$4:$B$1048576,"철원",'차단기 트립 진행 내역'!$P$4:$P$1048576,"대상",'차단기 트립 진행 내역'!$M$4:$M$1048576,"조치완료") -> 22 | S9: =COUNTIFS('차단기 트립 진행 내역'!$B$4:$B$1048576,"화천",'차단기 트립 진행 내역'!$P$4:$P$1048576,"대상",'차단기 트립 진행 내역'!$M$4:$M$1048576,"조치완료") -> 9 | T9: =SUM(N9:S9) -> 113
B10: 조치율 | C10: =C9/C4 -> 0.96153846 | D10: =D9/D4 -> 0.95833333 | E10: =E9/E4 -> 0.93548387 | F10: =F9/F4 -> 1 | G10: =G9/G4 -> 0.96551724 | H10: =H9/H4 -> 0.94736842 | I10: =I9/I4 -> 0.95897436 | M10: 조치율 | N10: =N9/N4 -> 0.95652174 | O10: =O9/O4 -> 0.91666667 | P10: =P9/P4 -> 0.95 | Q10: =Q9/Q4 -> 1 | R10: =R9/R4 -> 0.95652174 | S10: =S9/S4 -> 1 | T10: =T9/T4 -> 0.95762712
M11: 특이사항 1. 농사용 계량기 차단기 : 계량기 함체 견고하지 않아 우천시 누수 예상 2. 전원함 2식 운용 : 전원함 1식 제거 후 직결처리 필요 3. 차단기 2중 사용 : 전원함이 있으나 계량기단 차단기 설치되어 계량기단 차단기 제거 필요 4. 자동복구형 차단기 미설치 : 누전차단기(ELB) 설치로 교체 5. 건물전원/산악지역의 전원선을 매립 대상 우천시 잦은 트립발생 6. SPD미설치 운용대상
M13: 구분 | P13: 대상 | Q13: 불량비율 | R13: 조치완료 | S13: 미조치 | T13: 조치율
M14: 불량원인 | N14: 양호 | P14: =COUNTIFS('차단기 트립 진행 내역'!$P$4:$P$1048576,"대상",'차단기 트립 진행 내역'!$N$4:$N$1048576,"양호") -> 47 | Q14: =P14/$T$4 -> 0.39830508 | R14: - | S14: - | T14: -
B15: ■ DORS-415정류기 Revision 진행 총괄 | N15: 차단기 불량 | P15: =COUNTIFS('차단기 트립 진행 내역'!$P$4:$P$1048576,"대상",'차단기 트립 진행 내역'!$N$4:$N$1048576,"차단기") -> 49 | Q15: =P15/$T$4 -> 0.41525424 | R15: =COUNTIFS('차단기 트립 진행 내역'!$P$4:$P$1048576,"대상",'차단기 트립 진행 내역'!$N$4:$N$1048576,"차단기",'차단기 트립 진행 내역'!$O$4:$O$1048576,"완료") -> 46 | S15: =P15-R15 -> 3 | T15: =R15/P15 -> 0.93877551
B16: 구분 | C16: 춘천 | D16: 양구 | E16: 홍천 | F16: 인제 | G16: 철원 | H16: 화천 | I16: 총대상 | N16: 차단기 : 자동복구 불가 차단기 | P16: =COUNTIFS('차단기 트립 진행 내역'!$P$4:$P$1048576,"대상",'차단기 트립 진행 내역'!$N$4:$N$1048576,"차단기(자동복구 불가 차단기)") -> 4 | Q16: =P16/$T$4 -> 0.033898305 | R16: =COUNTIFS('차단기 트립 진행 내역'!$P$4:$P$1048576,"대상",'차단기 트립 진행 내역'!$N$4:$N$1048576,"차단기(자동복구 불가 차단기)",'차단기 트립 진행 내역'!$O$4:$O$1048576,"완료") -> 4 | S16: =P16-R16 -> 0 | T16: =R16/P16 -> 1
B17: 불량 대상 | C17: =COUNTIF('DORS415 리비전 미완료 진행 내역'!$B$4:$B$1048576,C16) -> 112 | D17: =COUNTIF('DORS415 리비전 미완료 진행 내역'!$B$4:$B$1048576,D16) -> 39 | E17: =COUNTIF('DORS415 리비전 미완료 진행 내역'!$B$4:$B$1048576,E16) -> 63 | F17: =COUNTIF('DORS415 리비전 미완료 진행 내역'!$B$4:$B$1048576,F16) -> 46 | G17: =COUNTIF('DORS415 리비전 미완료 진행 내역'!$B$4:$B$1048576,G16) -> 12 | H17: =COUNTIF('DORS415 리비전 미완료 진행 내역'!$B$4:$B$1048576,H16) -> 23 | I17: =SUM(C17:H17) -> 295 | N17: 장비 | P17: =COUNTIFS('차단기 트립 진행 내역'!$P$4:$P$1048576,"대상",'차단기 트립 진행 내역'!$N$4:$N$1048576,"장비") -> 9 | Q17: =P17/$T$4 -> 0.076271186 | R17: =COUNTIFS('차단기 트립 진행 내역'!$P$4:$P$1048576,"대상",'차단기 트립 진행 내역'!$N$4:$N$1048576,"장비",'차단기 트립 진행 내역'!$O$4:$O$1048576,"완료") -> 8 | S17: =P17-R17 -> 1 | T17: =R17/P17 -> 0.88888889
B18: 완료 | C18: =COUNTIFS('DORS415 리비전 미완료 진행 내역'!$B$4:$B$1048576,C16,'DORS415 리비전 미완료 진행 내역'!$G$4:$G$1048576,"완료") -> 109 | D18: =COUNTIFS('DORS415 리비전 미완료 진행 내역'!$B$4:$B$1048576,D16,'DORS415 리비전 미완료 진행 내역'!$G$4:$G$1048576,"완료") -> 37 | E18: =COUNTIFS('DORS415 리비전 미완료 진행 내역'!$B$4:$B$1048576,E16,'DORS415 리비전 미완료 진행 내역'!$G$4:$G$1048576,"완료") -> 61 | F18: =COUNTIFS('DORS415 리비전 미완료 진행 내역'!$B$4:$B$1048576,F16,'DORS415 리비전 미완료 진행 내역'!$G$4:$G$1048576,"완료") -> 43 | G18: =COUNTIFS('DORS415 리비전 미완료 진행 내역'!$B$4:$B$1048576,G16,'DORS415 리비전 미완료 진행 내역'!$G$4:$G$1048576,"완료") -> 11 | H18: =COUNTIFS('DORS415 리비전 미완료 진행 내역'!$B$4:$B$1048576,H16,'DORS415 리비전 미완료 진행 내역'!$G$4:$G$1048576,"완료") -> 20 | I18: =SUM(C18:H18) -> 281 | N18: 누수 | P18: =COUNTIFS('차단기 트립 진행 내역'!$P$4:$P$1048576,"대상",'차단기 트립 진행 내역'!$N$4:$N$1048576,"누수") -> 6 | Q18: =P18/$T$4 -> 0.050847458 | R18: =COUNTIFS('차단기 트립 진행 내역'!$P$4:$P$1048576,"대상",'차단기 트립 진행 내역'!$N$4:$N$1048576,"누수",'차단기 트립 진행 내역'!$O$4:$O$1048576,"완료") -> 6 | S18: =P18-R18 -> 0 | T18: =R18/P18 -> 1
B19: 미완료 | C19: =C17-C18 -> 3 | D19: =D17-D18 -> 2 | E19: =E17-E18 -> 2 | F19: =F17-F18 -> 3 | G19: =G17-G18 -> 1 | H19: =H17-H18 -> 3 | I19: =I17-I18 -> 14 | N19: 전원선로 | P19: =COUNTIFS('차단기 트립 진행 내역'!$P$4:$P$1048576,"대상",'차단기 트립 진행 내역'!$N$4:$N$1048576,"전원선로") -> 3 | Q19: =P19/$T$4 -> 0.025423729 | R19: =COUNTIFS('차단기 트립 진행 내역'!$P$4:$P$1048576,"대상",'차단기 트립 진행 내역'!$N$4:$N$1048576,"전원선로",'차단기 트립 진행 내역'!$O$4:$O$1048576,"완료") -> 2 | S19: =P19-R19 -> 1 | T19: =R19/P19 -> 0.66666667
B20: 조치율 | C20: =C18/C17 -> 0.97321429 | D20: =D18/D17 -> 0.94871795 | E20: =E18/E17 -> 0.96825397 | F20: =F18/F17 -> 0.93478261 | G20: =G18/G17 -> 0.91666667 | H20: =H18/H17 -> 0.86956522 | I20: =I18/I17 -> 0.95254237 | N20: 불량 총대상 | P20: =SUM(P15:P19) -> 71 | R20: =SUM(R15:R19) -> 66 | S20: =SUM(S15:S19) -> 5 | T20: =R20/P20 -> 0.92957746
M23: *차단기(자동복구 불가 차단기) : ELB 사용 *장비 : 정류기,PSU(W망),LORA 불량으로 인한 절연저항 불량 *누수 : 농사용계량기 및 W망 장비 누수 *전원선로 : 공용 또는 단독 매립/공가 포설 구간
B26: 차단기 내재화 지급(총20) | C26: 사용 | D26: 이승규 | E26: 김재성 | F26: 박영모 | G26: 정주영
B27: 20 | C27: 2 | D27: 5 | E27: 5 | F27: 1 | G27: 1
M29: 특이사항 1. 농사용 계량기 차단기 : 계량기 함체 견고하지 않아 우천시 누수 예상 2. 전원함 2식 운용 : 전원함 1식 제거 후 직결처리 필요 3. 차단기 2중 사용 : 전원함이 있으나 계량기단 차단기 설치되어 계량기단 차단기 제거 필요 4. 자동복구형 차단기 미설치 : 누전차단기(ELB) 설치로 교체 5. 건물전원/산악지역의 전원선을 매립/공가 대상 우천시 잦은 트립발생(SPD 설치 예정) 6. SPD미설치 운용대상

Sheet 차단기 트립 진행 내역
A2: ■ 차단기 트립 대상 | J2: 23년6월8일~ | W2: 2회 방문 | Z2: 3회 방문 | AC2: 4회 방문 | AF2: 5회 방문 | AI2: 6회 방문 | AL2: 7회 방문 | AO2: 8회 방문 | AR2: 9회 방문 | AU2: 10회 방문
A3: 순번 | B3: 지역 | C3: 통합시설코드 | D3: 국소명 | F3: 날짜 | H3: 차단기 타입 | I3: 트립 차단기 위치 | J3: 발생건수 | K3: 차단기 상태 | L3: 절연저항 | M3: 점검진행 | N3: 불량원인 | O3: 조치결과 | P3: KEY MISSION 대상 | Q3: 조치 날짜 | R3: 조치자 | S3: 조치내역 | T3: 기타 내역 | U3: SPD설치 유무 | V3: ACTA 등록 여부 | W3: 대응자 | X3: 대응날짜 | Y3: 점검내역 | Z3: 대응자 | AA3: 대응날짜 | AB3: 점검내역 | AC3: 대응자 | AD3: 대응날짜 | AE3: 점검내역 | AF3: 대응자 | AG3: 대응날짜 | AH3: 점검내역 | AI3: 대응자 | AJ3: 대응날짜 | AK3: 점검내역 | AL3: 대응자 | AM3: 대응날짜 | AN3: 점검내역 | AO3: 대응자 | AP3: 대응날짜 | AQ3: 점검내역 | AR3: 대응자 | AS3: 대응날짜 | AT3: 점검내역 | AU3: 대응자 | AV3: 대응날짜 | AW3: 점검내역
A4: 1 | B4: 인제 | C4: 2023Z9308 | D4: LGR_NK_인제설악산용아장성_B5.56.LTE.RRH_L(NSN) | F4: 45085 | G4: 박준성 | H4: 미확인 | J4: =COUNTA(G4,W4,Z4,AC4,AF4,AI4,AL4,AO4,AR4,AU4) -> 1 | K4: 미확인 | L4: 양호 | M4: 조치완료 | N4: 양호 | O4: 완료 | P4: 대상 | Q4: 46064 | R4: BP사 | S4: 이설로 점검 불필요 | V4: 불필요
A5: 2 | B5: 인제 | C5: 200721650 | D5: 인제한계령휴게소OW.56.WCDMA.E3-NODEB(외) | F5: 45085 | G5: 이승규 | H5: 미확인 | I5: 분전반 내 W차단기 | J5: =COUNTA(G5,W5,Z5,AC5,AF5,AI5,AL5,AO5,AR5,AU5) -> 1 | K5: 미확인 | L5: 불량 | M5: 조치완료 | N5: 장비 | O5: 완료 | P5: 대상 | Q5: 46091 | R5: 이상대, 이승규 | S5: W기지국 정류기 함체 교체 후 양호, 절연저항 양호 | U5: 유 | V5: 불필요
A6: 3 | B6: 홍천 | C6: 20122A77H | D6: NK_홍천천현2_B5.56.LTE.RRH_L(NSN) | F6: 45085 | G6: 박준성 | H6: IELB | J6: =COUNTA(G6,W6,Z6,AC6,AF6,AI6,AL6,AO6,AR6,AU6) -> 1 | K6: 불량 | M6: 조치완료 | O6: 완료 | Q6: 45092 | R6: 박윤근 | S6: NIELB 30A 교체완료
A7: 4 | B7: 양구 | C7: 200939268 | D7: 양구생태식물원2WOT.56.WCDMA.TTA-W20 | F7: 45085 | G7: 박준성 | H7: IELB20 | I7: 전원함 | J7: =COUNTA(G7,W7,Z7,AC7,AF7,AI7,AL7,AO7,AR7,AU7) -> 1 | K7: 불량 | M7: 조치완료 | O7: 완료 | Q7: 45092 | R7: 박준성 | S7: NIELB 30A 교체완료
A8: 5 | B8: 춘천 | C8: 2018Z3858 | D8: LGR_NK_춘천라데나GC_MTH(B53).56.LTE.RO-MIBOS-T-L60 | F8: 45085 | G8: 이상민 | H8: ELB20 | I8: 건물측 1차 | J8: =COUNTA(G8,W8,Z8,AC8,AF8,AI8,AL8,AO8,AR8,AU8) -> 2 | K8: 양호 | M8: 조치완료 | O8: 완료 | Q8: 45128 | R8: 이상민 | S8: 유비 건물측 20A ELB 잦은 차단기 트립으로 배선용 차단기설치 및 1차 케이블 굵기불량 교체 완료 | T8: 건물측 차단기 ON (ELB) | W8: 이상민 | X8: 45117 | Y8: 차단기ON
A9: 6 | B9: 춘천 | C9: 20173A69W | D9: LGR_NK_춘천의암옥광산_B7.56.LTE.RRU_2.6G_FRHG(NSN) | F9: 45085 | G9: 이승규 | H9: 미확인 | J9: =COUNTA(G9,W9,Z9,AC9,AF9,AI9,AL9,AO9,AR9,AU9) -> 1 | K9: 불량 | M9: 조치완료 | O9: 완료 | Q9: 2025-07-03 | R9: 유비 | S9: 차단기 교체 완료
A10: 7 | B10: 춘천 | C10: 200939824 | D10: 춘천의암2터널DOR.56.WCDMA.LR-DUON5 | F10: 45085 | G10: 이승규 | H10: IGR20A | I10: 전원함 | J10: =COUNTA(G10,W10,Z10,AC10,AF10,AI10,AL10,AO10,AR10,AU10) -> 1 | K10: 미확인 | L10: 불량 | M10: 조치완료 | N10: 장비 | O10: 완료 | P10: 대상 | Q10: 46064 | R10: 박영모, 이상민 | S10: OM PSU불량으로 현재 절연저항 1MΩ이하 측정되며, 우천시 추가 불량으로 트립예상, 전원함 2식 구성 중계기로 차단기 1식 제거하여 직결처리 완료, PSU교체 후 양호 | T10: PSU(W망) | U10: 무 | V10: 불필요
A11: 8 | B11: 홍천 | C11: 2009Z3495 | D11: 홍천삼마치위에높은터DOR.56.WCDMA.OR-DUOR2 | F11: 45085 | G11: 조범신 | H11: IGR20A | J11: =COUNTA(G11,W11,Z11,AC11,AF11,AI11,AL11,AO11,AR11,AU11) -> 1 | K11: 불량 | M11: 조치완료 | O11: 완료 | Q11: 45096 | R11: 박윤근 | S11: NIELB 30A 교체완료
A12: 9 | B12: 춘천 | C12: 2006Z0953 | D12: 춘천안보2WRF.56.WCDMA.SRF-W20 | F12: 45085 | G12: 이승규 | H12: 배선용 50A | I12: 계량기함체 1차 | J12: =COUNTA(G12,W12,Z12,AC12,AF12,AI12,AL12,AO12,AR12,AU12) -> 2 | K12: 양호 | L12: 양호 | M12: 조치완료 | N12: 전원선로 | O12: 완료 | P12: 대상 | Q12: 46091 | R12: 김재성 | S12: 계량기 단배선용 차단기트립으로 절연저항 양호함, 계량기 단에서 야산으로 50m포설되어 있음 낙뇌시 순간 전압상승으로 트립이 예상되며 계량기 함에서 SPD 설치 검토 | V12: 불필요 | W12: 현규진 | X12: 45497 | Y12: 차단기ON
A13: 10 | B13: 춘천 | C13: 201131508 | D13: 춘천제이드가든RHU0.56.WCDMA.RHU-DUON20-OMHU | E13: KT선로며 절연저항은 2메가옴으로 기준양호로 미시행 | F13: 45085 | G13: 이승규 | H13: ELB30A | I13: 건물측 분전반 1차 | J13: =COUNTA(G13,W13,Z13,AC13,AF13,AI13,AL13,AO13,AR13,AU13) -> 2 | K13: 양호 | L13: 불량 | M13: 점검완료 | N13: 전원선로 | P13: 대상 | R13: 이상민 | S13: 건물측 공용차단기 절연저항값이 2MΩ이하로 장비단까지 선로구간 우천시 추가 절연저항 불량하여 트립이 예상됨 KT주관 예상으로 재포설이 필요하나 추가 트립시 현장에서 추가 점검 예정 | T13: 건물측 차단기 배선용으로 변경 필요 | V13: 불필요 | W13: 조범신 | X13: 45497 | Y13: 차단기ON
A14: 11 | B14: 춘천 | C14: 2018Z3954 | D14: LGR_NK_춘천남면관천리마을CRU.56.LTE.CRU_L10(NSN) | F14: 45088 | G14: 고득훈 | H14: 미확인 | I14: 전원함 | J14: =COUNTA(G14,W14,Z14,AC14,AF14,AI14,AL14,AO14,AR14,AU14) -> 2 | K14: 불량 | M14: 조치완료 | O14: 완료 | Q14: 45190 | R14: 고득훈 | S14: NIELB 30A 교체완료 | T14: 낙뇌로 인한 차단기 불량예상 | W14: 고득훈
A15: 12 | B15: 춘천 | C15: 200933712 | D15: 춘천제이드팰리스2WIC.56.WCDMA.ICS-WN5 | F15: 45088 | G15: 고득훈 | H15: 미확인 | J15: =COUNTA(G15,W15,Z15,AC15,AF15,AI15,AL15,AO15,AR15,AU15) -> 4 | K15: 불량 | M15: 조치완료 | O15: 완료 | Q15: 45241 | R15: 유비 | S15: 전원함속판교체 요청 (완료) | T15: 3사 공용 차단기 트립 | W15: 이승규 | X15: 45086 | Y15: 차단기ON | Z15: 이상대 | AA15: 45161 | AB15: 차단기ON | AC15: 고득훈
A16: 13 | B16: 춘천 | C16: 2010Y4025 | D16: 춘천오항내평3WMC.56.WCDMA.WAFMCB | F16: 45088 | G16: 고득훈 | H16: 미확인 | J16: =COUNTA(G16,W16,Z16,AC16,AF16,AI16,AL16,AO16,AR16,AU16) -> 2 | K16: 불량 | M16: 조치완료 | O16: 완료 | Q16: 45241 | R16: 유비 | S16: NIELB 30A 교체완료, 전원함속판교체 요청(완료) | T16: (10/27)박준성 : 농사용계량기이하 차단기 누수 발생으로 전원함으로 변경필요 | W16: 박준성 | X16: 45225 | Y16: 농사용 계량기 누수
A17: 14 | B17: 양구 | C17: 20122B3IK | D17: NK_양구고방산3_B5.56.LTE.RRH_L(NSN) | F17: 45088 | G17: 박준성 | H17: 미확인 | J17: =COUNTA(G17,W17,Z17,AC17,AF17,AI17,AL17,AO17,AR17,AU17) -> 1 | K17: 불량 | M17: 조치완료 | O17: 완료 | Q17: 45241 | R17: 유비 | S17: 전원함속판교체 요청 (완료)
A18: 15 | B18: 양구 | C18: 2010Y0360 | D18: 양구한전7025RHU0.56.WCDMA.RHU-DUON5-OMHU | F18: 45088 | G18: 이승규 | H18: 미확인 | I18: 계량기함체 1차 | J18: =COUNTA(G18,W18,Z18,AC18,AF18,AI18,AL18,AO18,AR18,AU18) -> 4 | K18: 불량 | M18: 조치완료 | O18: 완료 | Q18: 45190 | R18: 고득훈 | S18: 계량기 이하 차단기 배선용 차단기로 교체 완료 | T18: 절연저항 및 누전체크 필요하며, 전원함 쪽 체크 필요 | W18: 이승규 | X18: 45104 | Y18: 차단기ON | Z18: 이승규 | AA18: 45117 | AB18: 차단기ON | AC18: 이승규 | AD18: 45203
A19: 16 | B19: 양구 | C19: 2009Z3437 | D19: 양구웅진수인WIC.56.WCDMA.ICS-W20 | F19: 45088 | G19: 박준성 | H19: 미확인 | J19: =COUNTA(G19,W19,Z19,AC19,AF19,AI19,AL19,AO19,AR19,AU19) -> 6 | K19: 불량 | M19: 조치완료 | O19: 완료 | Q19: 45190 | R19: 고득훈 | S19: NIELB 30A 교체완료 | W19: 이승규 | X19: 45086 | Y19: 차단기ON | Z19: 이승규 | AA19: 45100 | AB19: 정류기 누전으로 교체 후 완료 | AC19: 현규진 | AD19: 45491 | AE19: 차단기 ON | AF19: 박영모 | AG19: 45490 | AH19: 차단기 ON | AI19: 한지영 | AJ19: 45510 | AK19: 차단기 ON
A20: 17 | B20: 양구 | C20: 201229069 | D20: LGR_NK_양구웅진3_B5.56.LTE.RU(NSN) | F20: 45088 | G20: 이승규 | H20: 미확인 | J20: =COUNTA(G20,W20,Z20,AC20,AF20,AI20,AL20,AO20,AR20,AU20) -> 2 | K20: 불량 | M20: 조치완료 | O20: 완료 | Q20: 45190 | R20: 고득훈 | S20: NIELB 30A 교체완료 | W20: 이승규 | X20: 45104 | Y20: 차단기ON
A21: 18 | B21: 양구 | C21: 20122B455 | D21: LGR_NK_양구선착장_B5.56.LTE.RRH_L(NSN) | F21: 45088 | G21: 이승규 | H21: 미확인 | J21: =COUNTA(G21,W21,Z21,AC21,AF21,AI21,AL21,AO21,AR21,AU21) -> 1 | K21: 불량 | M21: 조치완료 | O21: 완료 | Q21: 45241 | R21: 유비 | S21: 전원함속판교체 요청 (완료)
A22: 19 | B22: 양구 | C22: 20122A76N | D22: NK_인제가아3_B5.56.LTE.RRH_L(NSN) | F22: 45088 | G22: 고득훈 | H22: 미확인 | J22: =COUNTA(G22,W22,Z22,AC22,AF22,AI22,AL22,AO22,AR22,AU22) -> 1 | K22: 불량 | M22: 조치완료 | O22: 완료 | Q22: 45241 | R22: 유비 | S22: 전원함속판교체 요청 (완료)
A23: 20 | B23: 양구 | C23: 20122A8N7 | D23: NK_인제해안2_B5.56.LTE.RRH_L(NSN) | F23: 45088 | G23: 고득훈 | H23: 미확인 | J23: =COUNTA(G23,W23,Z23,AC23,AF23,AI23,AL23,AO23,AR23,AU23) -> 1 | K23: 불량 | M23: 조치완료 | O23: 완료 | Q23: 45241 | R23: 유비 | S23: 전원함속판교체 요청 (완료)
A24: 21 | B24: 화천 | C24: 200738186 | D24: 화천대성산DMC.56.1X.SF-DUO20 | F24: 45088 | G24: 안병걸 | H24: ELB | J24: =COUNTA(G24,W24,Z24,AC24,AF24,AI24,AL24,AO24,AR24,AU24) -> 1 | K24: 양호 | L24: 양호 | M24: 조치완료 | N24: 양호 | O24: 완료 | P24: 대상 | Q24: 46091 | R24: 김재성 | S24: 절연저항 양호 및 자동복구양호, 기존 IELB에서 IGR로 교체 확인되었으며 최근 유비 교체 예상 | T24: NIELB 교체필요 | U24: 유 | V24: 불필요
A25: 22 | B25: 인제 | C25: 200738517 | D25: 인제가아6WMC.56.WCDMA.SF-W20 | F25: 45088 | G25: 고득훈 | H25: 미확인 | J25: =COUNTA(G25,W25,Z25,AC25,AF25,AI25,AL25,AO25,AR25,AU25) -> 2 | K25: 양호 | M25: 조치완료 | O25: 완료 | Q25: 45190 | R25: 고득훈 | S25: NIELB 30A 교체완료 | W25: 선우영 | X25: 45117 | Y25: 차단기ON
A26: 23 | B26: 철원 | C26: 2009Z1854 | D26: 철원내대3WRF.56.WCDMA.SRF-W20 | F26: 45088 | G26: 안병걸 | H26: IGR20A | J26: =COUNTA(G26,W26,Z26,AC26,AF26,AI26,AL26,AO26,AR26,AU26) -> 2 | K26: 불량 | L26: 양호 | M26: 조치완료 | N26: 차단기 | O26: 완료 | P26: 대상 | Q26: 45292 | R26: 유비 | S26: 차단기 교체 완료 | V26: 불필요 | W26: 유호열 | X26: 45497 | Y26: 차단기ON
A27: 24 | B27: 철원 | C27: 20122A8GH | D27: NK_철원상사4_B5.56.LTE.RRH_L(NSN) | F27: 45088 | G27: 안병걸 | H27: IGR20A | I27: 전원함 | J27: =COUNTA(G27,W27,Z27,AC27,AF27,AI27,AL27,AO27,AR27,AU27) -> 1 | K27: 양호 | L27: 양호 | M27: 조치완료 | N27: 양호 | O27: 완료 | P27: 대상 | Q27: 46071 | R27: 김재성 | S27: 절연저항 양호, 자동복구 양호 | U27: 유 | V27: 불필요
A28: 25 | B28: 화천 | C28: 20222A20L | D28: LGR_NK_화천해산터널진입로2_B5.56.LTE.RRH_L(NSN) | F28: 45088 | G28: 안병걸 | H28: 미확인 | J28: =COUNTA(G28,W28,Z28,AC28,AF28,AI28,AL28,AO28,AR28,AU28) -> 2 | K28: 불량 | M28: 조치완료 | O28: 완료 | Q28: 45117 | R28: 안병걸 | S28: NIELB 30A 교체완료 | T28: 교체 후 재발생으로 누전 점검작업 후 양호 | W28: 안병걸 | X28: 45117 | Y28: 차단기ON
A29: 26 | B29: 화천 | C29: 201033603 | D29: 화천유촌4DOR.56.WCDMA.OR-DUO2 | F29: 45088 | G29: 안병걸 | H29: IELB20A | I29: 전원함 | J29: =COUNTA(G29,W29,Z29,AC29,AF29,AI29,AL29,AO29,AR29,AU29) -> 1 | K29: 불량 | L29: 양호 | M29: 조치완료 | N29: 차단기 | O29: 완료 | P29: 대상 | Q29: 46063 | R29: 조성룡, 김재성 | S29: 차단기 자동복구 불량으로 ACTA등록 완료(절연저항양호), 자동복구 교체 완료 및 OM PSU 절연저항 저조로 교체 완료 | V29: 완료
A30: 27 | B30: 인제 | C30: 201336444 | D30: NK_인제하늘정원펜션_B5.56.LTE.RRH_L(NSN) | F30: 45104 | G30: 선우영 | H30: IGR20A | I30: 분전함 1차 | J30: =COUNTA(G30,W30,Z30,AC30,AF30,AI30,AL30,AO30,AR30,AU30) -> 1 | K30: 양호 | M30: 조치완료 | O30: 완료 | Q30: 45241 | R30: 유비 | S30: 전원함속판교체 요청 (완료)
A31: 28 | B31: 양구 | C31: 200939423 | D31: 양구오미5WMC.56.WCDMA.SF-W20 | F31: 45104 | G31: 이승규 | H31: 미확인 | J31: =COUNTA(G31,W31,Z31,AC31,AF31,AI31,AL31,AO31,AR31,AU31) -> 1 | K31: 미확인 | M31: 조치완료 | O31: 완료 | Q31: 45241 | R31: 유비 | S31: 전원함속판교체 요청 (완료)
A32: 29 | B32: 춘천 | C32: 2009Z1312 | D32: 춘천한덕3RHU0.56.WCDMA.RHU-DUON5-MHU | F32: 45110 | G32: 현규진 | H32: IELB20A | I32: 전원함 | J32: =COUNTA(G32,W32,Z32,AC32,AF32,AI32,AL32,AO32,AR32,AU32) -> 1 | K32: 불량 | M32: 조치완료 | O32: 완료 | Q32: 45190 | R32: 고득훈 | S32: NIELB 30A 교체완료
A33: 30 | B33: 춘천 | C33: 201135200 | D33: 춘천팔미7DOR.56.WCDMA.OR-DUORC6 | F33: 45110 | G33: 박영모 | H33: IELB20A | I33: 농사용계량기 | J33: =COUNTA(G33,W33,Z33,AC33,AF33,AI33,AL33,AO33,AR33,AU33) -> 2 | K33: 양호 | L33: 양호 | M33: 조치완료 | O33: 완료 | Q33: 45110 | R33: 박영모 | S33: IELB20A, 농사용계량기 고무패킹 설치 완료 절연저항 양호, | W33: 박영모 | X33: 26년8월
A34: 31 | B34: 철원 | C34: 2018Y7925 | D34: 철원사요노동당사WMC.56.WCDMA.SF-W20 | F34: 45112 | G34: 한지영 | H34: 지능형IGR20A | I34: 전원함 | J34: =COUNTA(G34,W34,Z34,AC34,AF34,AI34,AL34,AO34,AR34,AU34) -> 1 | K34: 양호 | L34: 양호 | M34: 조치완료 | N34: 양호 | O34: 완료 | P34: 대상 | Q34: 46071 | R34: 김재성 | S34: 절연저항양호, 자동복구 양호 | U34: 유 | V34: 불필요
A35: 32 | B35: 양구 | C35: 20122B3IH | D35: LGR_NK_양구고대2_B5.56.LTE.RRH_L(NSN) | F35: 45113 | G35: 선우영 | H35: IELB20A | J35: =COUNTA(G35,W35,Z35,AC35,AF35,AI35,AL35,AO35,AR35,AU35) -> 1 | K35: 불량 | M35: 조치완료 | O35: 완료 | Q35: 45113 | R35: 선우영 | S35: IELB20A 교체 후 자동 복구 양호
A36: 33 | B36: 춘천 | C36: 20122A8JF | D36: LGR_NK_춘천유포2_B5.56.LTE.RRH_L(NSN) | F36: 45117 | G36: 이상민 | H36: IELB30A | I36: 전원함 | J36: =COUNTA(G36,W36,Z36,AC36,AF36,AI36,AL36,AO36,AR36,AU36) -> 2 | K36: 불량 | L36: 양호 | M36: 조치완료 | N36: 차단기 | O36: 완료 | P36: 대상 | Q36: 46064 | R36: 박영모, 이상민 | S36: 차단기불량으로 추가 ACTA 등록 완료(절연저항 양호), BP작업 완료 | T36: 자동복구 불량으로 남스 등록 완료 | V36: 완료 | W36: 이상민 | X36: 45525 | Y36: 차단기ON
A37: 34 | B37: 춘천 | C37: 2010Y1236 | D37: 춘천원무2WMC.56.WCDMA.SF-W20 | F37: 45117 | G37: 박영모 | H37: ELB30A | I37: 와이어블 분전반 | J37: =COUNTA(G37,W37,Z37,AC37,AF37,AI37,AL37,AO37,AR37,AU37) -> 1 | K37: 양호 | L37: 양호 | M37: 조치완료 | N37: 차단기 | O37: 완료 | P37: 대상 | Q37: 46066 | R37: 박영모, 이상민 | S37: SKT 전원함 내 IELB 자동복구 불량 및 W망 ELB수용되어 있어 IGR변경 및 W망 수용 후 완료 | T37: 와이어블 분전반 단 발생시 직결처리 예정 | U37: 유 | V37: 불필요
A38: 35 | B38: 춘천 | C38: 200635057 | D38: 춘천정족2WMC.56.WCDMA.SF-W20 | F38: 45117 | G38: 박영모 | H38: IGR20A | I38: 전원함 | J38: =COUNTA(G38,W38,Z38,AC38,AF38,AI38,AL38,AO38,AR38,AU38) -> 1 | K38: 불량 | M38: 조치완료 | O38: 완료 | Q38: 45117 | R38: 박영모 | S38: IGR불량으로 IELB교체 양호
A39: 36 | B39: 춘천 | C39: 20193B6TI | D39: EL_춘천우두LH2차지하1_IRO_IB(B5W).56.LTE.RO-IRO-D( | F39: 45117 | G39: 정민석 | H39: 배선용30A | I39: 통합분전반 | J39: =COUNTA(G39,W39,Z39,AC39,AF39,AI39,AL39,AO39,AR39,AU39) -> 1 | K39: 양호 | L39: 양호 | M39: 조치완료 | N39: 양호 | O39: 완료 | P39: 대상 | Q39: 46078 | R39: 이상민 | S39: 인빌딩내 배선용차단기로 절연저항양호하며, '23년 당시 전기작업으로 인한 OFF 예상, 23년 이후 미발생 | U39: 유 | V39: 불필요
A40: 37 | B40: 춘천 | C40: 20122B3LX | D40: LGR_NK_춘천오항산막골_B5.56.LTE.RRH_L(NSN) | F40: 45117 | G40: 이상민 | H40: IELB20A | I40: 계량기함체 1차 | J40: =COUNTA(G40,W40,Z40,AC40,AF40,AI40,AL40,AO40,AR40,AU40) -> 2 | K40: 양호 | M40: 조치완료 | O40: 완료 | Q40: 45241 | R40: 유비 | S40: 우천시 잦은차단기 트립이며 계량기함체, 전원함체 IELB 2중 설치로 계량기 함체 차단기 제거 후 직결, 전원함속판교체 완료 | W40: 이승규
A41: 38 | B41: 춘천 | C41: 20202A53R | D41: LGR_NK_춘천오항내평2_B5.56.LTE.RRH_L(NSN) | F41: 45124 | G41: 이상민 | H41: IGR20A 지능형 | I41: 1차 분전반 | J41: =COUNTA(G41,W41,Z41,AC41,AF41,AI41,AL41,AO41,AR41,AU41) -> 1 | K41: 양호 | M41: 조치완료 | O41: 완료 | T41: 차단기 상태 수동으로 자동변경후 TEST시 자동복구 양호
...

Sheet DORS415 리비전 미완료 진행 내역
A2: ■ DORS415 리비전 미완료 대상
A3: 순번 | B3: 지역 | C3: 통합시설코드 | D3: 국소명 | E3: 날짜 | F3: 대응자 | G3: 완료유무 | H3: 작업자 | I3: 조치 날짜
A4: 1 | B4: 양구 | C4: 20172A3ZZ | D4: LGR_NK_GR_양구정림3_B7.56.LTE.RRU_2.6G_FRHG(NSN) | E4: 45108 | F4: 이승규 | G4: 완료 | H4: 이상대 | I4: 45259
A5: 2 | B5: 양구 | C5: 20122B453 | D5: LGR_NK_양구석현2_B5.56.LTE.RRH_L(NSN) | E5: 45108 | F5: 이승규 | G5: 완료 | H5: 이상대 | I5: 45265
A6: 3 | B6: 양구 | C6: 20213AH3Z | D6: LGR_NK_양구안대리2_B7.56.LTE.RRU_2.6G_FRHG(NSN) | E6: 45108 | F6: 이승규 | G6: 완료 | H6: 이승규 | I6: 45279
A7: 4 | B7: 양구 | C7: 20122A7JC | D7: LGR_NK_양구여중고_B5.56.LTE.RRH_L(NSN) | E7: 45108 | F7: 이승규 | G7: 완료 | H7: 이승규 | I7: 45279
A8: 5 | B8: 양구 | C8: 20122B3P8 | D8: LGR_NK_양구월명도일_B5.56.LTE.RRH_L(NSN) | E8: 45108 | F8: 박영모 | G8: 완료 | H8: 이상대 | I8: 45149
A9: 6 | B9: 양구 | C9: 20122B3P9 | D9: LGR_NK_양구월명도일2_B5.56.LTE.RRH_L(NSN) | E9: 45108 | F9: 박영모 | G9: 완료 | H9: 이승규 | I9: 45149
A10: 7 | B10: 양구 | C10: 20163A4PC | D10: LGR_NK_양구월명리4_B3.56.LTE.RRU_FHEB(NSN) | E10: 45108 | F10: 박영모 | G10: 완료 | H10: 이승규 | I10: 45149
A11: 8 | B11: 양구 | C11: 2014Z7953 | D11: LGR_NK_양구죽리OL_B3.56.LTE.RRU_FHEB(NSN) | E11: 45108 | F11: 이승규 | G11: 완료 | H11: 이승규 | I11: 45169
A12: 9 | B12: 화천 | C12: 20122B40E | D12: NK_화천상서칠성교_B5.56.LTE.RRH_L(NSN) | E12: 45110 | F12: 안병걸 | G12: 완료 | H12: 안병걸 | I12: 45133
A13: 10 | B13: 춘천 | C13: 20122A8JP | D13: LGR_NK_춘천행촌_B5.56.LTE.RRH_L(NSN) | E13: 45110 | F13: 박준성 | G13: 완료 | H13: 박준성 | I13: 45120
A14: 11 | B14: 춘천 | C14: 20122B3I4 | D14: LGR_NK_춘천남산면우러니_B5.56.LTE.RRH_L(NSN) | E14: 45110 | F14: 박준성 | G14: 완료 | H14: 박준성 | I14: 45133
A15: 12 | B15: 춘천 | C15: 20122B3W6 | D15: LGR_NK_춘천행촌봉의텃골2_B5.56.LTE.RRH_L(NSN) | E15: 45110 | F15: 박준성 | G15: 완료 | H15: 박준성 | I15: 45120
... A21: 18 | B21: 인제 | C21: 20122B3EC | D21: NK_인제서화6_B5.56.LTE.RRH_L(NSN) | E21: 45117 | F21: 현규진 | G21: 완료 | H21: 선우영 | I21: 45121
A22: 19 | B22: 철원 | D22: 철원문혜OL3-B7DRIU | E22: 45117 | F22: 한지영 | G22: 완료 | H22: 한지영 | I22: 45188
A23: 20 | B23: 화천 | C23: 20123ADHN | D23: LGR_NK_화천간동방천_B5.56.LTE.RRH_L(NSN) | E23: 45117 | F23: 조성룡 | G23: 완료 | H23: 안병걸 | I23: 45121
A24: 21 | B24: 화천 | C24: 20122A85I | D24: KTR_NK_화천용담계곡_B5.56.LTE.RRH_L(NSN) | E24: 45117 | F24: 이상대 | G24: 완료 | H24: 안병걸 | I24: 45149
A25: 22 | B25: 화천 | C25: 20213AH47 | D25: KTR_NK_화천용담계곡_B7.56.LTE.RRU_2.6G_FRHG(NSN) | E25: 45117 | F25: 이상대 | G25: 완료 | H25: 안병걸 | I25: 45149
A26: 23 | B26: 화천 | C26: 20193AFM0 | D26: KTR_NK_화천7사단칠성훈련장_B3.56.LTE.RRU_FHEB(NSN) | E26: 45117 | F26: 안병걸 | G26: 완료 | H26: 안병걸 | I26: 45133
A27: 24 | B27: 홍천 | C27: 20123AG7R | D27: NK_홍천어론황정골_B5.56.LTE.RRH_L(NSN) | E27: 45119 | F27: 선우영 | G27: 완료 | H27: 이상대 | I27: 46045
A28: 25 | B28: 화천 | C28: 2016Y0349 | D28: KTR_NK_화천광덕기상대_B3.56.LTE.RRU_FHEB(NSN) | E28: 45119 | F28: 고득훈 | G28: 완료 | H28: 안병걸 | I28: 45121
A29: 26 | B29: 홍천 | C29: 20173A668 | D29: NK_홍천내촌봉수대도둠터_B7.56.LTE.RRU_2.6G_FRHG(NS | E29: 45124 | F29: 선우영 | G29: 완료 | H29: 선우영 | I29: 45133
A30: 27 | B30: 인제 | C30: 20122B3DT | D30: NK_인제서리입석동5_B5.56.LTE.RRH_L(NSN) | E30: 45124 | F30: 선우영 | G30: 완료 | H30: 선우영 | I30: 45133
A31: 28 | B31: 철원 | C31: 202127552 | D31: 철원지경1961부대-_B3.56.LTE.RRU_FHEB(NSN) | E31: 45133 | F31: 한지영 | G31: 완료 | H31: 한지영 | I31: 45133
A32: 29 | B32: 철원 | C32: 2018Z4116 | D32: NK_철원3사단18소초_B3.56.LTE.RRU_FHEB(NSN) | E32: 45133 | F32: 한지영 | G32: 완료 | H32: 한지영 | I32: 45133
A33: 30 | B33: 철원 | C33: 2018Z4156 | D33: NK_철원6사단풍암마현도로_B3.56.LTE.RRU_FHEB(NSN) | E33: 45133 | F33: 한지영 | G33: 완료 | H33: 한지영 | I33: 45188
A34: 31 | B34: 철원 | C34: 20173A6EB | D34: NK_철원도창청전펜션_B7.56.LTE.RRU_2.6G_FRHG(NSN) | E34: 45133 | F34: 한지영 | G34: 완료 | H34: 한지영 | I34: 45188
... A72: 69 | B72: 홍천 | C72: 20123ADL8 | D72: NK_홍천괘석달음재2_B5.56.LTE.RRH_L(NSN) | E72: 45230 | F72: 김기현 | G72: 완료 | H72: 이상대 | I72: 46132
A73: 70 | B73: 춘천 | C73: 20122A8KB | D73: LGR_NK_춘천감정3_B5.56.LTE.RRH_L(NSN) | E73: 45235 | F73: 이상민
A74: 71 | B74: 춘천 | C74: 20122A794 | D74: LGR_NK_춘천고성2_B5.56.LTE.RRH_L(NSN) | E74: 45235 | F74: 박영모 | G74: 완료 | H74: 박영모 | I74: 45235
A75: 72 | B75: 인제 | C75: 20193BZXX | D75: NK_인제개인약수입구_B5.56.LTE.RRH_L(NSN) | E75: 45235 | F75: 박준성 | G75: 완료 | H75: 이승규 | I75: 46132
A76: 73 | B76: 인제 | C76: 20122B3QM | D76: NK_인제하남왜골_B5.56.LTE.RRH_L(NSN) | E76: 45235 | F76: 박준성 | G76: 완료 | H76: 박준성 | I76: 45279
A77: 74 | B77: 인제 | C77: 20123AGAV | D77: NK_인제오미재_B5.56.LTE.RRH_L(NSN) | E77: 45235 | F77: 박준성 | G77: 완료 | H77: 이승규 | I77: 46132
A78: 75 | B78: 홍천 | C78: 20122A7SX | D78: NK_홍천모둘자리2_B5.56.LTE.RRH_L(NSN) | E78: 45235 | F78: 박준성 | G78: 완료 | H78: 선우영 | I78: 45560
A79: 76 | B79: 춘천 | C79: 20122A7XI | D79: LGR_NK_춘천제이드팰리스1_B5.56.LTE.RRH_L(NSN) | E79: 45243 | F79: 이상민 | G79: 완료 | H79: 이상민 | I79: 45243
A80: 77 | B80: 양구 | C80: 20122A6KU | D80: NK_양구두무2_B5.56.LTE.RRH_L(NSN) | E80: 45245 | F80: 박준성 | G80: 완료 | H80: 박준성 | I80: 45245
A81: 78 | B81: 양구 | C81: 20122B374 | D81: NK_양구아랫두무_B5.56.LTE.RRH_L(NSN) | E81: 45245 | F81: 박준성 | G81: 완료 | H81: 박준성 | I81: 45245
A82: 79 | B82: 춘천 | C82: 2021Y9023 | D82: EL_춘천국민체육센타_B5.56.LTE.RRU_800M_R2212(ELG) | E82: 45259 | F82: 박영모 | G82: 완료 | H82: 이승규 | I82: 45268
A83: 80 | B83: 춘천 | C83: 2021Y9901 | D83: EL_춘천국민체육센타_B3.56.LTE.RRUS13(ELG) | E83: 45259 | F83: 박영모 | G83: 완료 | H83: 이승규 | I83: 45268
...

Sheet W단독 고지국소
A2: ■ W단독 고지국소
A3: 순번 | B3: 지역 | C3: 통합시설코드 | D3: 국소명 | E3: 문제점 | F3: 완료여부
A4: 1 | B4: 화천 | C4: 200721583 | D4: 화천원천OW.56.WCDMA.E3-NODEB(외) | E4: W단독 고지국소
A5: 2 | B5: 화천 | C5: 200721911 | D5: 화천검단OW.56.WCDMA.E3-NODEB(외) | E5: W단독 고지국소
A6: 3 | B6: 홍천 | C6: 200721937 | D6: 홍천화촌3OW.56.WCDMA.E3-NODEB(외) | E6: W단독 고지국소
A7: 4 | B7: 양구 | C7: 200721597 | D7: 양구오미2FXW.56.WCDMA.FX-NODEB | E7: W단독 고지국소
A8: 5 | B8: 철원 | C8: 200721619 | D8: 철원상사3OW.56.WCDMA.E3-NODEB(외) | E8: W단독 고지국소
A9: 6 | B9: 춘천 | C9: 200939893 | D9: 춘천품걸FXW.56.WCDMA.FX-NODEB | E9: W단독 오지국소
A10: 7 | B10: 화천 | C10: 200721757 | D10: 화천용담2OW.56.WCDMA.E3-NODEB(외) | E10: W단독 고지국소
A11: 8 | B11: 춘천 | C11: 200721817 | D11: 춘천백양2OW.56.WCDMA.E3-NODEB(외) | E11: W단독 고지국소
A12: 9 | B12: 양구 | C12: 2008Z8095 | D12: 양구구암2OW.56.WCDMA.E3-NODEB(외) | E12: W단독 고지국소
A13: 10 | B13: 홍천 | C13: 200721632 | D13: 홍천성동OW.56.WCDMA.E3-NODEB(외) | E13: W단독 고지국소
A14: 11 | B14: 화천 | C14: 200721720 | D14: 화천주파령OW.56.WCDMA.E3-NODEB(외) | E14: W단독 고지국소, 민통선
A15: 12
A81: 78
A82: 79
A83: 80
A84: 81
A85: 82
A86: 83
A87: 84
A88: 85
A89: 86
A90: 87
A91: 88
... A100: 97

Sheet LTE 노출형 DU
A2: ■ LTE 노출형 DU
A3: 순번 | B3: 지역 | C3: 통합시설코드 | D3: 국소명 | E3: 문제점 | F3: 완료여부
A4: 1 | B4: 화천 | C4: 2018Y2955 | D4: 화천백암PX삼거리L-DU1.56.LTE.DU20(내) | E4: LTE노출형 DU
A5: 2 | B5: 화천 | C5: 201321473 | D5: 화천수상령중대OL-DU1.56.LTE.DU20(내) | E5: LTE노출형 DU
A6: 3 | B6: 춘천 | C6: 20122A659 | D6: 춘천안보OL-DU1.56.LTE.ENB(외) | E6: LTE노출형 DU
A7: 4 | B7: 화천 | C7: 202424328 | D7: 화천산양3OL-DU1.56.LTE.DU20(외) | E7: LTE노출형 DU | F7: 완료
A8: 5 | B8: 인제 | C8: 20172A4RN | D8: 인제을지부대OL-DU1.56.LTE.DU20(내) | E8: LTE노출형 DU | F8: 완료
A9: 6 | B9: 양구 | C9: 20122A5VW | D9: 양구사태리L-DU1.56.LTE.DU20(외) | E9: LTE노출형 DU
A10: 7 | B10: 철원 | C10: 2018Y2866 | D10: 철원제2땅굴4OL-DU1.56.LTE.DU20(내) | E10: LTE노출형 DU
A11: 8 | B11: 홍천 | C11: 2018Y2875 | D11: 홍천생둔OL-DU1.56.LTE.DU20(내) | E11: LTE노출형 DU
A12: 9 | B12: 홍천 | C12: 20122A69T | D12: 홍천노천2OL-DU1.56.LTE.DU20(외) | E12: LTE노출형 DU
A13: 10 | B13: 철원 | C13: 20122A643 | D13: 철원지경OL-DU1.56.LTE.DU20(외) | E13: LTE노출형 DU
A14: 11 | B14: 양구 | C14: 2016Y7221 | D14: 양구팔랑폭포OL-DU1.56.LTE.ENB(내) | E14: LTE노출형 DU
A15: 12 | B15: 양구 | C15: 20172AFUL | D15: 양구방산OL-DU1.56.LTE.DU20(내) | E15: LTE노출형 DU
A16: 13 | B16: 춘천 | C16: 20122A650 | D16: 춘천광판OL-DU1.56.LTE.DU20(외) | E16: LTE노출형 DU
A81: 78
A82: 79
A83: 80
A84: 81
A85: 82
A86: 83
A87: 84
A88: 85
A89: 86
A90: 87
A91: 88
A92: 89
... A100: 97

Sheet 사진
